[2025-02-20T07:33:25.159+0000] {taskinstance.py:1979} INFO - Dependencies all met for dep_context=non-requeueable deps ti=<TaskInstance: scraping_news_dag.scrapping_nytimes manual__2025-02-20T07:33:24.249632+00:00 [queued]>
[2025-02-20T07:33:25.169+0000] {taskinstance.py:1979} INFO - Dependencies all met for dep_context=requeueable deps ti=<TaskInstance: scraping_news_dag.scrapping_nytimes manual__2025-02-20T07:33:24.249632+00:00 [queued]>
[2025-02-20T07:33:25.169+0000] {taskinstance.py:2193} INFO - Starting attempt 1 of 1
[2025-02-20T07:33:25.182+0000] {taskinstance.py:2214} INFO - Executing <Task(_PythonDecoratedOperator): scrapping_nytimes> on 2025-02-20 07:33:24.249632+00:00
[2025-02-20T07:33:25.186+0000] {standard_task_runner.py:60} INFO - Started process 270 to run task
[2025-02-20T07:33:25.190+0000] {standard_task_runner.py:87} INFO - Running: ['airflow', 'tasks', 'run', 'scraping_news_dag', 'scrapping_nytimes', 'manual__2025-02-20T07:33:24.249632+00:00', '--job-id', '156', '--raw', '--subdir', 'DAGS_FOLDER/scraping-news-dag.py', '--cfg-path', '/tmp/tmp3n5seqq2']
[2025-02-20T07:33:25.192+0000] {standard_task_runner.py:88} INFO - Job 156: Subtask scrapping_nytimes
[2025-02-20T07:33:25.206+0000] {logging_mixin.py:188} WARNING - /home/airflow/.local/lib/python3.9/site-packages/airflow/settings.py:194 DeprecationWarning: The sql_alchemy_conn option in [core] has been moved to the sql_alchemy_conn option in [database] - the old setting has been used, but please update your config.
[2025-02-20T07:33:25.238+0000] {task_command.py:423} INFO - Running <TaskInstance: scraping_news_dag.scrapping_nytimes manual__2025-02-20T07:33:24.249632+00:00 [running]> on host deproject-airflow-scheduler
[2025-02-20T07:33:25.321+0000] {taskinstance.py:2510} INFO - Exporting env vars: AIRFLOW_CTX_DAG_OWNER='airflow' AIRFLOW_CTX_DAG_ID='scraping_news_dag' AIRFLOW_CTX_TASK_ID='scrapping_nytimes' AIRFLOW_CTX_EXECUTION_DATE='2025-02-20T07:33:24.249632+00:00' AIRFLOW_CTX_TRY_NUMBER='1' AIRFLOW_CTX_DAG_RUN_ID='manual__2025-02-20T07:33:24.249632+00:00'
[2025-02-20T07:33:25.978+0000] {logger.py:11} INFO - ====== WebDriver manager ======
[2025-02-20T07:33:26.324+0000] {logger.py:11} INFO - Get LATEST chromedriver version for google-chrome
[2025-02-20T07:33:26.459+0000] {logger.py:11} INFO - Get LATEST chromedriver version for google-chrome
[2025-02-20T07:33:26.557+0000] {logger.py:11} INFO - There is no [linux64] chromedriver "133.0.6943.126" for browser google-chrome "133.0.6943" in cache
[2025-02-20T07:33:26.558+0000] {logger.py:11} INFO - Get LATEST chromedriver version for google-chrome
[2025-02-20T07:33:26.775+0000] {logger.py:11} INFO - WebDriver version 133.0.6943.126 selected
[2025-02-20T07:33:26.781+0000] {logger.py:11} INFO - Modern chrome version https://storage.googleapis.com/chrome-for-testing-public/133.0.6943.126/linux64/chromedriver-linux64.zip
[2025-02-20T07:33:26.782+0000] {logger.py:11} INFO - About to download new driver from https://storage.googleapis.com/chrome-for-testing-public/133.0.6943.126/linux64/chromedriver-linux64.zip
[2025-02-20T07:33:26.929+0000] {logger.py:11} INFO - Driver downloading response is 200
[2025-02-20T07:33:28.840+0000] {logger.py:11} INFO - Get LATEST chromedriver version for google-chrome
[2025-02-20T07:33:29.061+0000] {logger.py:11} INFO - Driver has been saved in cache [/home/airflow/.wdm/drivers/chromedriver/linux64/133.0.6943.126]
[2025-02-20T07:34:02.761+0000] {logging_mixin.py:188} INFO - Total scraped: 100
[2025-02-20T07:35:23.727+0000] {taskinstance.py:2728} ERROR - Task failed with exception
Traceback (most recent call last):
  File "/home/airflow/.local/lib/python3.9/site-packages/pandas/core/indexes/base.py", line 3080, in get_loc
    return self._engine.get_loc(casted_key)
  File "pandas/_libs/index.pyx", line 70, in pandas._libs.index.IndexEngine.get_loc
  File "pandas/_libs/index.pyx", line 101, in pandas._libs.index.IndexEngine.get_loc
  File "pandas/_libs/hashtable_class_helper.pxi", line 4554, in pandas._libs.hashtable.PyObjectHashTable.get_item
  File "pandas/_libs/hashtable_class_helper.pxi", line 4562, in pandas._libs.hashtable.PyObjectHashTable.get_item
KeyError: 'date'

The above exception was the direct cause of the following exception:

Traceback (most recent call last):
  File "/home/airflow/.local/lib/python3.9/site-packages/airflow/models/taskinstance.py", line 444, in _execute_task
    result = _execute_callable(context=context, **execute_callable_kwargs)
  File "/home/airflow/.local/lib/python3.9/site-packages/airflow/models/taskinstance.py", line 414, in _execute_callable
    return execute_callable(context=context, **execute_callable_kwargs)
  File "/home/airflow/.local/lib/python3.9/site-packages/airflow/decorators/base.py", line 241, in execute
    return_value = super().execute(context)
  File "/home/airflow/.local/lib/python3.9/site-packages/airflow/operators/python.py", line 200, in execute
    return_value = self.execute_callable()
  File "/home/airflow/.local/lib/python3.9/site-packages/airflow/operators/python.py", line 217, in execute_callable
    return self.python_callable(*self.op_args, **self.op_kwargs)
  File "/opt/airflow/dags/scraping-news-dag.py", line 26, in scrapping_nytimes
    df = nyt.main()
  File "/opt/airflow/dags/source/nyt.py", line 91, in main
    result = transform(articles, result)
  File "/opt/airflow/dags/source/nyt.py", line 68, in transform
    df['date'] = pd.to_datetime(df['date'], utc=True)
  File "/home/airflow/.local/lib/python3.9/site-packages/pandas/core/frame.py", line 3024, in __getitem__
    indexer = self.columns.get_loc(key)
  File "/home/airflow/.local/lib/python3.9/site-packages/pandas/core/indexes/base.py", line 3082, in get_loc
    raise KeyError(key) from err
KeyError: 'date'
[2025-02-20T07:35:23.742+0000] {taskinstance.py:1149} INFO - Marking task as FAILED. dag_id=scraping_news_dag, task_id=scrapping_nytimes, execution_date=20250220T073324, start_date=20250220T073325, end_date=20250220T073523
[2025-02-20T07:35:23.760+0000] {standard_task_runner.py:107} ERROR - Failed to execute job 156 for task scrapping_nytimes ('date'; 270)
[2025-02-20T07:35:23.810+0000] {local_task_job_runner.py:234} INFO - Task exited with return code 1
[2025-02-20T07:35:23.826+0000] {taskinstance.py:3309} INFO - 0 downstream tasks scheduled from follow-on schedule check
