[2025-02-20T07:33:25.159+0000] {taskinstance.py:1979} INFO - Dependencies all met for dep_context=non-requeueable deps ti=<TaskInstance: scraping_news_dag.scrapping_cnn manual__2025-02-20T07:33:24.249632+00:00 [queued]>
[2025-02-20T07:33:25.169+0000] {taskinstance.py:1979} INFO - Dependencies all met for dep_context=requeueable deps ti=<TaskInstance: scraping_news_dag.scrapping_cnn manual__2025-02-20T07:33:24.249632+00:00 [queued]>
[2025-02-20T07:33:25.169+0000] {taskinstance.py:2193} INFO - Starting attempt 1 of 1
[2025-02-20T07:33:25.182+0000] {taskinstance.py:2214} INFO - Executing <Task(_PythonDecoratedOperator): scrapping_cnn> on 2025-02-20 07:33:24.249632+00:00
[2025-02-20T07:33:25.186+0000] {standard_task_runner.py:60} INFO - Started process 271 to run task
[2025-02-20T07:33:25.190+0000] {standard_task_runner.py:87} INFO - Running: ['airflow', 'tasks', 'run', 'scraping_news_dag', 'scrapping_cnn', 'manual__2025-02-20T07:33:24.249632+00:00', '--job-id', '157', '--raw', '--subdir', 'DAGS_FOLDER/scraping-news-dag.py', '--cfg-path', '/tmp/tmpj2fle49d']
[2025-02-20T07:33:25.192+0000] {standard_task_runner.py:88} INFO - Job 157: Subtask scrapping_cnn
[2025-02-20T07:33:25.206+0000] {logging_mixin.py:188} WARNING - /home/airflow/.local/lib/python3.9/site-packages/airflow/settings.py:194 DeprecationWarning: The sql_alchemy_conn option in [core] has been moved to the sql_alchemy_conn option in [database] - the old setting has been used, but please update your config.
[2025-02-20T07:33:25.238+0000] {task_command.py:423} INFO - Running <TaskInstance: scraping_news_dag.scrapping_cnn manual__2025-02-20T07:33:24.249632+00:00 [running]> on host deproject-airflow-scheduler
[2025-02-20T07:33:25.322+0000] {taskinstance.py:2510} INFO - Exporting env vars: AIRFLOW_CTX_DAG_OWNER='airflow' AIRFLOW_CTX_DAG_ID='scraping_news_dag' AIRFLOW_CTX_TASK_ID='scrapping_cnn' AIRFLOW_CTX_EXECUTION_DATE='2025-02-20T07:33:24.249632+00:00' AIRFLOW_CTX_TRY_NUMBER='1' AIRFLOW_CTX_DAG_RUN_ID='manual__2025-02-20T07:33:24.249632+00:00'
[2025-02-20T07:34:51.894+0000] {taskinstance.py:2728} ERROR - Task failed with exception
Traceback (most recent call last):
  File "/home/airflow/.local/lib/python3.9/site-packages/pandas/core/indexes/base.py", line 3080, in get_loc
    return self._engine.get_loc(casted_key)
  File "pandas/_libs/index.pyx", line 70, in pandas._libs.index.IndexEngine.get_loc
  File "pandas/_libs/index.pyx", line 101, in pandas._libs.index.IndexEngine.get_loc
  File "pandas/_libs/hashtable_class_helper.pxi", line 4554, in pandas._libs.hashtable.PyObjectHashTable.get_item
  File "pandas/_libs/hashtable_class_helper.pxi", line 4562, in pandas._libs.hashtable.PyObjectHashTable.get_item
KeyError: 'date'

The above exception was the direct cause of the following exception:

Traceback (most recent call last):
  File "/home/airflow/.local/lib/python3.9/site-packages/airflow/models/taskinstance.py", line 444, in _execute_task
    result = _execute_callable(context=context, **execute_callable_kwargs)
  File "/home/airflow/.local/lib/python3.9/site-packages/airflow/models/taskinstance.py", line 414, in _execute_callable
    return execute_callable(context=context, **execute_callable_kwargs)
  File "/home/airflow/.local/lib/python3.9/site-packages/airflow/decorators/base.py", line 241, in execute
    return_value = super().execute(context)
  File "/home/airflow/.local/lib/python3.9/site-packages/airflow/operators/python.py", line 200, in execute
    return_value = self.execute_callable()
  File "/home/airflow/.local/lib/python3.9/site-packages/airflow/operators/python.py", line 217, in execute_callable
    return self.python_callable(*self.op_args, **self.op_kwargs)
  File "/opt/airflow/dags/scraping-news-dag.py", line 20, in scrapping_cnn
    df = cnn.main()
  File "/opt/airflow/dags/source/cnn.py", line 78, in main
    df['date'] = pd.to_datetime(df['date'])
  File "/home/airflow/.local/lib/python3.9/site-packages/pandas/core/frame.py", line 3024, in __getitem__
    indexer = self.columns.get_loc(key)
  File "/home/airflow/.local/lib/python3.9/site-packages/pandas/core/indexes/base.py", line 3082, in get_loc
    raise KeyError(key) from err
KeyError: 'date'
[2025-02-20T07:34:51.910+0000] {taskinstance.py:1149} INFO - Marking task as FAILED. dag_id=scraping_news_dag, task_id=scrapping_cnn, execution_date=20250220T073324, start_date=20250220T073325, end_date=20250220T073451
[2025-02-20T07:34:51.924+0000] {standard_task_runner.py:107} ERROR - Failed to execute job 157 for task scrapping_cnn ('date'; 271)
[2025-02-20T07:34:51.959+0000] {local_task_job_runner.py:234} INFO - Task exited with return code 1
[2025-02-20T07:34:51.982+0000] {taskinstance.py:3309} INFO - 0 downstream tasks scheduled from follow-on schedule check
