[2025-02-19T08:42:05.360+0000] {taskinstance.py:1979} INFO - Dependencies all met for dep_context=non-requeueable deps ti=<TaskInstance: scraping_news_dag.scrapping_nytimes manual__2025-02-19T08:42:02.433329+00:00 [queued]>
[2025-02-19T08:42:05.380+0000] {taskinstance.py:1979} INFO - Dependencies all met for dep_context=requeueable deps ti=<TaskInstance: scraping_news_dag.scrapping_nytimes manual__2025-02-19T08:42:02.433329+00:00 [queued]>
[2025-02-19T08:42:05.381+0000] {taskinstance.py:2193} INFO - Starting attempt 1 of 1
[2025-02-19T08:42:05.408+0000] {taskinstance.py:2214} INFO - Executing <Task(_PythonDecoratedOperator): scrapping_nytimes> on 2025-02-19 08:42:02.433329+00:00
[2025-02-19T08:42:05.417+0000] {standard_task_runner.py:60} INFO - Started process 661 to run task
[2025-02-19T08:42:05.423+0000] {standard_task_runner.py:87} INFO - Running: ['airflow', 'tasks', 'run', 'scraping_news_dag', 'scrapping_nytimes', 'manual__2025-02-19T08:42:02.433329+00:00', '--job-id', '115', '--raw', '--subdir', 'DAGS_FOLDER/scraping-news-dag.py', '--cfg-path', '/tmp/tmp55w8k6eu']
[2025-02-19T08:42:05.427+0000] {standard_task_runner.py:88} INFO - Job 115: Subtask scrapping_nytimes
[2025-02-19T08:42:05.454+0000] {logging_mixin.py:188} WARNING - /home/airflow/.local/lib/python3.9/site-packages/airflow/settings.py:194 DeprecationWarning: The sql_alchemy_conn option in [core] has been moved to the sql_alchemy_conn option in [database] - the old setting has been used, but please update your config.
[2025-02-19T08:42:05.523+0000] {task_command.py:423} INFO - Running <TaskInstance: scraping_news_dag.scrapping_nytimes manual__2025-02-19T08:42:02.433329+00:00 [running]> on host deproject-airflow-scheduler
[2025-02-19T08:42:05.716+0000] {taskinstance.py:2510} INFO - Exporting env vars: AIRFLOW_CTX_DAG_OWNER='airflow' AIRFLOW_CTX_DAG_ID='scraping_news_dag' AIRFLOW_CTX_TASK_ID='scrapping_nytimes' AIRFLOW_CTX_EXECUTION_DATE='2025-02-19T08:42:02.433329+00:00' AIRFLOW_CTX_TRY_NUMBER='1' AIRFLOW_CTX_DAG_RUN_ID='manual__2025-02-19T08:42:02.433329+00:00'
[2025-02-19T08:42:48.340+0000] {taskinstance.py:2728} ERROR - Task failed with exception
Traceback (most recent call last):
  File "/home/airflow/.local/lib/python3.9/site-packages/airflow/models/taskinstance.py", line 444, in _execute_task
    result = _execute_callable(context=context, **execute_callable_kwargs)
  File "/home/airflow/.local/lib/python3.9/site-packages/airflow/models/taskinstance.py", line 414, in _execute_callable
    return execute_callable(context=context, **execute_callable_kwargs)
  File "/home/airflow/.local/lib/python3.9/site-packages/airflow/decorators/base.py", line 241, in execute
    return_value = super().execute(context)
  File "/home/airflow/.local/lib/python3.9/site-packages/airflow/operators/python.py", line 200, in execute
    return_value = self.execute_callable()
  File "/home/airflow/.local/lib/python3.9/site-packages/airflow/operators/python.py", line 217, in execute_callable
    return self.python_callable(*self.op_args, **self.op_kwargs)
  File "/opt/airflow/dags/scraping-news-dag.py", line 26, in scrapping_nytimes
    df = nyt.main()
  File "/opt/airflow/dags/source/nyt.py", line 73, in main
    driver = setup_driver()
  File "/opt/airflow/dags/source/nyt.py", line 12, in setup_driver
    driver = webdriver.Chrome()
  File "/home/airflow/.local/lib/python3.9/site-packages/selenium/webdriver/chrome/webdriver.py", line 45, in __init__
    super().__init__(
  File "/home/airflow/.local/lib/python3.9/site-packages/selenium/webdriver/chromium/webdriver.py", line 66, in __init__
    super().__init__(command_executor=executor, options=options)
  File "/home/airflow/.local/lib/python3.9/site-packages/selenium/webdriver/remote/webdriver.py", line 250, in __init__
    self.start_session(capabilities)
  File "/home/airflow/.local/lib/python3.9/site-packages/selenium/webdriver/remote/webdriver.py", line 342, in start_session
    response = self.execute(Command.NEW_SESSION, caps)["value"]
  File "/home/airflow/.local/lib/python3.9/site-packages/selenium/webdriver/remote/webdriver.py", line 429, in execute
    self.error_handler.check_response(response)
  File "/home/airflow/.local/lib/python3.9/site-packages/selenium/webdriver/remote/errorhandler.py", line 232, in check_response
    raise exception_class(message, screen, stacktrace)
selenium.common.exceptions.SessionNotCreatedException: Message: session not created: probably user data directory is already in use, please specify a unique value for --user-data-dir argument, or don't use --user-data-dir
Stacktrace:
#0 0x5580375cabea <unknown>
#1 0x5580370687d0 <unknown>
#2 0x5580370a1c05 <unknown>
#3 0x55803709d96f <unknown>
#4 0x5580370ee3a9 <unknown>
#5 0x5580370ed8d6 <unknown>
#6 0x5580370df863 <unknown>
#7 0x5580370abac8 <unknown>
#8 0x5580370acc31 <unknown>
#9 0x55803759418b <unknown>
#10 0x558037598112 <unknown>
#11 0x55803758104c <unknown>
#12 0x558037598d04 <unknown>
#13 0x5580375654bf <unknown>
#14 0x5580375b9528 <unknown>
#15 0x5580375b96f9 <unknown>
#16 0x5580375c9a66 <unknown>
#17 0x7efe5f554134 <unknown>

[2025-02-19T08:42:48.377+0000] {taskinstance.py:1149} INFO - Marking task as FAILED. dag_id=scraping_news_dag, task_id=scrapping_nytimes, execution_date=20250219T084202, start_date=20250219T084205, end_date=20250219T084248
[2025-02-19T08:42:48.412+0000] {standard_task_runner.py:107} ERROR - Failed to execute job 115 for task scrapping_nytimes (Message: session not created: probably user data directory is already in use, please specify a unique value for --user-data-dir argument, or don't use --user-data-dir
Stacktrace:
#0 0x5580375cabea <unknown>
#1 0x5580370687d0 <unknown>
#2 0x5580370a1c05 <unknown>
#3 0x55803709d96f <unknown>
#4 0x5580370ee3a9 <unknown>
#5 0x5580370ed8d6 <unknown>
#6 0x5580370df863 <unknown>
#7 0x5580370abac8 <unknown>
#8 0x5580370acc31 <unknown>
#9 0x55803759418b <unknown>
#10 0x558037598112 <unknown>
#11 0x55803758104c <unknown>
#12 0x558037598d04 <unknown>
#13 0x5580375654bf <unknown>
#14 0x5580375b9528 <unknown>
#15 0x5580375b96f9 <unknown>
#16 0x5580375c9a66 <unknown>
#17 0x7efe5f554134 <unknown>
; 661)
[2025-02-19T08:42:48.454+0000] {local_task_job_runner.py:234} INFO - Task exited with return code 1
[2025-02-19T08:42:48.506+0000] {taskinstance.py:3309} INFO - 0 downstream tasks scheduled from follow-on schedule check
