[2025-02-20T07:37:25.890+0000] {taskinstance.py:1979} INFO - Dependencies all met for dep_context=non-requeueable deps ti=<TaskInstance: scraping_news_dag.scrapping_cnn manual__2025-02-20T07:37:24.519261+00:00 [queued]>
[2025-02-20T07:37:25.903+0000] {taskinstance.py:1979} INFO - Dependencies all met for dep_context=requeueable deps ti=<TaskInstance: scraping_news_dag.scrapping_cnn manual__2025-02-20T07:37:24.519261+00:00 [queued]>
[2025-02-20T07:37:25.904+0000] {taskinstance.py:2193} INFO - Starting attempt 1 of 1
[2025-02-20T07:37:25.919+0000] {taskinstance.py:2214} INFO - Executing <Task(_PythonDecoratedOperator): scrapping_cnn> on 2025-02-20 07:37:24.519261+00:00
[2025-02-20T07:37:25.925+0000] {standard_task_runner.py:60} INFO - Started process 1931 to run task
[2025-02-20T07:37:25.928+0000] {standard_task_runner.py:87} INFO - Running: ['airflow', 'tasks', 'run', 'scraping_news_dag', 'scrapping_cnn', 'manual__2025-02-20T07:37:24.519261+00:00', '--job-id', '158', '--raw', '--subdir', 'DAGS_FOLDER/scraping-news-dag.py', '--cfg-path', '/tmp/tmpj3giiwg0']
[2025-02-20T07:37:25.930+0000] {standard_task_runner.py:88} INFO - Job 158: Subtask scrapping_cnn
[2025-02-20T07:37:25.950+0000] {logging_mixin.py:188} WARNING - /home/airflow/.local/lib/python3.9/site-packages/airflow/settings.py:194 DeprecationWarning: The sql_alchemy_conn option in [core] has been moved to the sql_alchemy_conn option in [database] - the old setting has been used, but please update your config.
[2025-02-20T07:37:25.997+0000] {task_command.py:423} INFO - Running <TaskInstance: scraping_news_dag.scrapping_cnn manual__2025-02-20T07:37:24.519261+00:00 [running]> on host deproject-airflow-scheduler
[2025-02-20T07:37:26.083+0000] {taskinstance.py:2510} INFO - Exporting env vars: AIRFLOW_CTX_DAG_OWNER='airflow' AIRFLOW_CTX_DAG_ID='scraping_news_dag' AIRFLOW_CTX_TASK_ID='scrapping_cnn' AIRFLOW_CTX_EXECUTION_DATE='2025-02-20T07:37:24.519261+00:00' AIRFLOW_CTX_TRY_NUMBER='1' AIRFLOW_CTX_DAG_RUN_ID='manual__2025-02-20T07:37:24.519261+00:00'
[2025-02-20T07:38:29.184+0000] {logging_mixin.py:188} WARNING - /home/airflow/.local/lib/python3.9/site-packages/dateutil/parser/_parser.py:1207 UnknownTimezoneWarning: tzname WIB identified but not understood.  Pass `tzinfos` argument in order to correctly return a timezone-aware datetime.  In a future version, this will raise an exception.
[2025-02-20T07:40:38.611+0000] {logging_mixin.py:188} INFO -                                                   url  ... source
0   https://edition.cnn.com/2025/02/18/politics/er...  ...    cnn
1   https://edition.cnn.com/2025/02/18/politics/do...  ...    cnn
2   https://edition.cnn.com/2025/02/17/politics/wh...  ...    cnn
3   https://edition.cnn.com/2025/02/18/politics/jf...  ...    cnn
4   https://edition.cnn.com/2025/02/19/politics/ed...  ...    cnn
..                                                ...  ...    ...
84  https://edition.cnn.com/2025/02/19/business/vi...  ...    cnn
85  https://edition.cnn.com/2025/02/20/economy/chi...  ...    cnn
86  https://edition.cnn.com/2025/02/19/business/tr...  ...    cnn
87  https://edition.cnn.com/2025/02/19/tech/trump-...  ...    cnn
88  https://edition.cnn.com/2025/02/20/economy/chi...  ...    cnn

[89 rows x 5 columns]
[2025-02-20T07:40:38.611+0000] {taskinstance.py:2728} ERROR - Task failed with exception
Traceback (most recent call last):
  File "/home/airflow/.local/lib/python3.9/site-packages/pandas/core/indexes/base.py", line 3080, in get_loc
    return self._engine.get_loc(casted_key)
  File "pandas/_libs/index.pyx", line 70, in pandas._libs.index.IndexEngine.get_loc
  File "pandas/_libs/index.pyx", line 101, in pandas._libs.index.IndexEngine.get_loc
  File "pandas/_libs/hashtable_class_helper.pxi", line 4554, in pandas._libs.hashtable.PyObjectHashTable.get_item
  File "pandas/_libs/hashtable_class_helper.pxi", line 4562, in pandas._libs.hashtable.PyObjectHashTable.get_item
KeyError: 'date'

The above exception was the direct cause of the following exception:

Traceback (most recent call last):
  File "/home/airflow/.local/lib/python3.9/site-packages/airflow/models/taskinstance.py", line 444, in _execute_task
    result = _execute_callable(context=context, **execute_callable_kwargs)
  File "/home/airflow/.local/lib/python3.9/site-packages/airflow/models/taskinstance.py", line 414, in _execute_callable
    return execute_callable(context=context, **execute_callable_kwargs)
  File "/home/airflow/.local/lib/python3.9/site-packages/airflow/decorators/base.py", line 241, in execute
    return_value = super().execute(context)
  File "/home/airflow/.local/lib/python3.9/site-packages/airflow/operators/python.py", line 200, in execute
    return_value = self.execute_callable()
  File "/home/airflow/.local/lib/python3.9/site-packages/airflow/operators/python.py", line 217, in execute_callable
    return self.python_callable(*self.op_args, **self.op_kwargs)
  File "/opt/airflow/dags/scraping-news-dag.py", line 20, in scrapping_cnn
    df = cnn.main()
  File "/opt/airflow/dags/source/cnn.py", line 90, in main
    print(result['date'])
  File "/home/airflow/.local/lib/python3.9/site-packages/pandas/core/frame.py", line 3024, in __getitem__
    indexer = self.columns.get_loc(key)
  File "/home/airflow/.local/lib/python3.9/site-packages/pandas/core/indexes/base.py", line 3082, in get_loc
    raise KeyError(key) from err
KeyError: 'date'
[2025-02-20T07:40:38.624+0000] {taskinstance.py:1149} INFO - Marking task as FAILED. dag_id=scraping_news_dag, task_id=scrapping_cnn, execution_date=20250220T073724, start_date=20250220T073725, end_date=20250220T074038
[2025-02-20T07:40:38.634+0000] {standard_task_runner.py:107} ERROR - Failed to execute job 158 for task scrapping_cnn ('date'; 1931)
[2025-02-20T07:40:38.682+0000] {local_task_job_runner.py:234} INFO - Task exited with return code 1
[2025-02-20T07:40:38.704+0000] {taskinstance.py:3309} INFO - 0 downstream tasks scheduled from follow-on schedule check
