[2025-02-10T09:36:00.272+0000] {taskinstance.py:1979} INFO - Dependencies all met for dep_context=non-requeueable deps ti=<TaskInstance: load_bigquery-test.get_csv_data manual__2025-02-10T09:34:48.178880+00:00 [queued]>
[2025-02-10T09:36:00.292+0000] {taskinstance.py:1979} INFO - Dependencies all met for dep_context=requeueable deps ti=<TaskInstance: load_bigquery-test.get_csv_data manual__2025-02-10T09:34:48.178880+00:00 [queued]>
[2025-02-10T09:36:00.293+0000] {taskinstance.py:2193} INFO - Starting attempt 1 of 1
[2025-02-10T09:36:00.321+0000] {taskinstance.py:2214} INFO - Executing <Task(PythonOperator): get_csv_data> on 2025-02-10 09:34:48.178880+00:00
[2025-02-10T09:36:00.330+0000] {standard_task_runner.py:60} INFO - Started process 1272 to run task
[2025-02-10T09:36:00.335+0000] {standard_task_runner.py:87} INFO - Running: ['airflow', 'tasks', 'run', 'load_bigquery-test', 'get_csv_data', 'manual__2025-02-10T09:34:48.178880+00:00', '--job-id', '39', '--raw', '--subdir', 'DAGS_FOLDER/load-bigquery-test.py', '--cfg-path', '/tmp/tmpc3qdlf67']
[2025-02-10T09:36:00.339+0000] {standard_task_runner.py:88} INFO - Job 39: Subtask get_csv_data
[2025-02-10T09:36:00.371+0000] {logging_mixin.py:188} WARNING - /home/airflow/.local/lib/python3.9/site-packages/airflow/settings.py:194 DeprecationWarning: The sql_alchemy_conn option in [core] has been moved to the sql_alchemy_conn option in [database] - the old setting has been used, but please update your config.
[2025-02-10T09:36:00.453+0000] {task_command.py:423} INFO - Running <TaskInstance: load_bigquery-test.get_csv_data manual__2025-02-10T09:34:48.178880+00:00 [running]> on host deproject-airflow-scheduler
[2025-02-10T09:36:00.620+0000] {taskinstance.py:2510} INFO - Exporting env vars: AIRFLOW_CTX_DAG_OWNER='dibimbing' AIRFLOW_CTX_DAG_ID='load_bigquery-test' AIRFLOW_CTX_TASK_ID='get_csv_data' AIRFLOW_CTX_EXECUTION_DATE='2025-02-10T09:34:48.178880+00:00' AIRFLOW_CTX_TRY_NUMBER='1' AIRFLOW_CTX_DAG_RUN_ID='manual__2025-02-10T09:34:48.178880+00:00'
[2025-02-10T09:36:00.984+0000] {taskinstance.py:2728} ERROR - Task failed with exception
Traceback (most recent call last):
  File "/home/airflow/.local/lib/python3.9/site-packages/airflow/models/taskinstance.py", line 444, in _execute_task
    result = _execute_callable(context=context, **execute_callable_kwargs)
  File "/home/airflow/.local/lib/python3.9/site-packages/airflow/models/taskinstance.py", line 414, in _execute_callable
    return execute_callable(context=context, **execute_callable_kwargs)
  File "/home/airflow/.local/lib/python3.9/site-packages/airflow/operators/python.py", line 200, in execute
    return_value = self.execute_callable()
  File "/home/airflow/.local/lib/python3.9/site-packages/airflow/operators/python.py", line 217, in execute_callable
    return self.python_callable(*self.op_args, **self.op_kwargs)
  File "/opt/airflow/dags/load-bigquery-test.py", line 26, in get_data
    df = pd.read_csv('/opt/airflow/data/test_output.csv', index=False)
TypeError: read_csv() got an unexpected keyword argument 'index'
[2025-02-10T09:36:01.007+0000] {taskinstance.py:1149} INFO - Marking task as FAILED. dag_id=load_bigquery-test, task_id=get_csv_data, execution_date=20250210T093448, start_date=20250210T093600, end_date=20250210T093601
[2025-02-10T09:36:01.040+0000] {standard_task_runner.py:107} ERROR - Failed to execute job 39 for task get_csv_data (read_csv() got an unexpected keyword argument 'index'; 1272)
[2025-02-10T09:36:01.075+0000] {local_task_job_runner.py:234} INFO - Task exited with return code 1
[2025-02-10T09:36:01.125+0000] {taskinstance.py:3309} INFO - 0 downstream tasks scheduled from follow-on schedule check
